[2025-05-04 17:41:19,719] ERROR log 27812 15524 Internal Server Error: /api/profile/3
[2025-05-04 17:41:20,136] ERROR log 27812 15524 Internal Server Error: /api/users/following/status/3
Traceback (most recent call last):
  File "C:\Users\aleja\Desktop\BINFO\TFB\Myqx\Myqx-bff\venv\Lib\site-packages\rest_framework\views.py", line 512, in dispatch
    response = handler(request, *args, **kwargs)
  File "C:\Users\aleja\Desktop\BINFO\TFB\Myqx\Myqx-bff\api\views\user_views.py", line 126, in get
    return self.users_controller.check_following(follower_id, followed_id)
           ^^^^^^^^^^^^^^^^^^^^^^^^^^^^^^^^^^^^^
AttributeError: 'UsersController' object has no attribute 'check_following'

During handling of the above exception, another exception occurred:

Traceback (most recent call last):
  File "C:\Users\aleja\Desktop\BINFO\TFB\Myqx\Myqx-bff\venv\Lib\site-packages\django\utils\module_loading.py", line 30, in import_string
    return cached_import(module_path, class_name)
  File "C:\Users\aleja\Desktop\BINFO\TFB\Myqx\Myqx-bff\venv\Lib\site-packages\django\utils\module_loading.py", line 16, in cached_import
    return getattr(module, class_name)
AttributeError: module 'api.utils' has no attribute 'custom_exception_handler'

The above exception was the direct cause of the following exception:

Traceback (most recent call last):
  File "C:\Users\aleja\Desktop\BINFO\TFB\Myqx\Myqx-bff\venv\Lib\site-packages\rest_framework\settings.py", line 179, in import_from_string
    return import_string(val)
  File "C:\Users\aleja\Desktop\BINFO\TFB\Myqx\Myqx-bff\venv\Lib\site-packages\django\utils\module_loading.py", line 32, in import_string
    raise ImportError(
    ...<2 lines>...
    ) from err
ImportError: Module "api.utils" does not define a "custom_exception_handler" attribute/class

During handling of the above exception, another exception occurred:

Traceback (most recent call last):
  File "C:\Users\aleja\Desktop\BINFO\TFB\Myqx\Myqx-bff\venv\Lib\site-packages\django\core\handlers\exception.py", line 55, in inner
    response = get_response(request)
  File "C:\Users\aleja\Desktop\BINFO\TFB\Myqx\Myqx-bff\venv\Lib\site-packages\django\core\handlers\base.py", line 197, in _get_response
    response = wrapped_callback(request, *callback_args, **callback_kwargs)
  File "C:\Users\aleja\Desktop\BINFO\TFB\Myqx\Myqx-bff\venv\Lib\site-packages\django\views\decorators\csrf.py", line 65, in _view_wrapper
    return view_func(request, *args, **kwargs)
  File "C:\Users\aleja\Desktop\BINFO\TFB\Myqx\Myqx-bff\venv\Lib\site-packages\django\views\generic\base.py", line 104, in view
    return self.dispatch(request, *args, **kwargs)
           ~~~~~~~~~~~~~^^^^^^^^^^^^^^^^^^^^^^^^^^
  File "C:\Users\aleja\Desktop\BINFO\TFB\Myqx\Myqx-bff\venv\Lib\site-packages\rest_framework\views.py", line 515, in dispatch
    response = self.handle_exception(exc)
  File "C:\Users\aleja\Desktop\BINFO\TFB\Myqx\Myqx-bff\venv\Lib\site-packages\rest_framework\views.py", line 469, in handle_exception
    exception_handler = self.get_exception_handler()
  File "C:\Users\aleja\Desktop\BINFO\TFB\Myqx\Myqx-bff\venv\Lib\site-packages\rest_framework\views.py", line 304, in get_exception_handler
    return self.settings.EXCEPTION_HANDLER
           ^^^^^^^^^^^^^^^^^^^^^^^^^^^^^^^
  File "C:\Users\aleja\Desktop\BINFO\TFB\Myqx\Myqx-bff\venv\Lib\site-packages\rest_framework\settings.py", line 227, in __getattr__
    val = perform_import(val, attr)
  File "C:\Users\aleja\Desktop\BINFO\TFB\Myqx\Myqx-bff\venv\Lib\site-packages\rest_framework\settings.py", line 168, in perform_import
    return import_from_string(val, setting_name)
  File "C:\Users\aleja\Desktop\BINFO\TFB\Myqx\Myqx-bff\venv\Lib\site-packages\rest_framework\settings.py", line 182, in import_from_string
    raise ImportError(msg)
ImportError: Could not import 'api.utils.custom_exception_handler' for API setting 'EXCEPTION_HANDLER'. ImportError: Module "api.utils" does not define a "custom_exception_handler" attribute/class.
[2025-05-04 17:41:54,388] ERROR log 27812 5372 Internal Server Error: /api/profile/3
[2025-05-04 17:41:54,632] ERROR log 27812 5372 Internal Server Error: /api/users/following/status/3
Traceback (most recent call last):
  File "C:\Users\aleja\Desktop\BINFO\TFB\Myqx\Myqx-bff\venv\Lib\site-packages\rest_framework\views.py", line 512, in dispatch
    response = handler(request, *args, **kwargs)
  File "C:\Users\aleja\Desktop\BINFO\TFB\Myqx\Myqx-bff\api\views\user_views.py", line 126, in get
    return self.users_controller.check_following(follower_id, followed_id)
           ^^^^^^^^^^^^^^^^^^^^^^^^^^^^^^^^^^^^^
AttributeError: 'UsersController' object has no attribute 'check_following'

During handling of the above exception, another exception occurred:

Traceback (most recent call last):
  File "C:\Users\aleja\Desktop\BINFO\TFB\Myqx\Myqx-bff\venv\Lib\site-packages\django\utils\module_loading.py", line 30, in import_string
    return cached_import(module_path, class_name)
  File "C:\Users\aleja\Desktop\BINFO\TFB\Myqx\Myqx-bff\venv\Lib\site-packages\django\utils\module_loading.py", line 16, in cached_import
    return getattr(module, class_name)
AttributeError: module 'api.utils' has no attribute 'custom_exception_handler'

The above exception was the direct cause of the following exception:

Traceback (most recent call last):
  File "C:\Users\aleja\Desktop\BINFO\TFB\Myqx\Myqx-bff\venv\Lib\site-packages\rest_framework\settings.py", line 179, in import_from_string
    return import_string(val)
  File "C:\Users\aleja\Desktop\BINFO\TFB\Myqx\Myqx-bff\venv\Lib\site-packages\django\utils\module_loading.py", line 32, in import_string
    raise ImportError(
    ...<2 lines>...
    ) from err
ImportError: Module "api.utils" does not define a "custom_exception_handler" attribute/class

During handling of the above exception, another exception occurred:

Traceback (most recent call last):
  File "C:\Users\aleja\Desktop\BINFO\TFB\Myqx\Myqx-bff\venv\Lib\site-packages\django\core\handlers\exception.py", line 55, in inner
    response = get_response(request)
  File "C:\Users\aleja\Desktop\BINFO\TFB\Myqx\Myqx-bff\venv\Lib\site-packages\django\core\handlers\base.py", line 197, in _get_response
    response = wrapped_callback(request, *callback_args, **callback_kwargs)
  File "C:\Users\aleja\Desktop\BINFO\TFB\Myqx\Myqx-bff\venv\Lib\site-packages\django\views\decorators\csrf.py", line 65, in _view_wrapper
    return view_func(request, *args, **kwargs)
  File "C:\Users\aleja\Desktop\BINFO\TFB\Myqx\Myqx-bff\venv\Lib\site-packages\django\views\generic\base.py", line 104, in view
    return self.dispatch(request, *args, **kwargs)
           ~~~~~~~~~~~~~^^^^^^^^^^^^^^^^^^^^^^^^^^
  File "C:\Users\aleja\Desktop\BINFO\TFB\Myqx\Myqx-bff\venv\Lib\site-packages\rest_framework\views.py", line 515, in dispatch
    response = self.handle_exception(exc)
  File "C:\Users\aleja\Desktop\BINFO\TFB\Myqx\Myqx-bff\venv\Lib\site-packages\rest_framework\views.py", line 469, in handle_exception
    exception_handler = self.get_exception_handler()
  File "C:\Users\aleja\Desktop\BINFO\TFB\Myqx\Myqx-bff\venv\Lib\site-packages\rest_framework\views.py", line 304, in get_exception_handler
    return self.settings.EXCEPTION_HANDLER
           ^^^^^^^^^^^^^^^^^^^^^^^^^^^^^^^
  File "C:\Users\aleja\Desktop\BINFO\TFB\Myqx\Myqx-bff\venv\Lib\site-packages\rest_framework\settings.py", line 227, in __getattr__
    val = perform_import(val, attr)
  File "C:\Users\aleja\Desktop\BINFO\TFB\Myqx\Myqx-bff\venv\Lib\site-packages\rest_framework\settings.py", line 168, in perform_import
    return import_from_string(val, setting_name)
  File "C:\Users\aleja\Desktop\BINFO\TFB\Myqx\Myqx-bff\venv\Lib\site-packages\rest_framework\settings.py", line 182, in import_from_string
    raise ImportError(msg)
ImportError: Could not import 'api.utils.custom_exception_handler' for API setting 'EXCEPTION_HANDLER'. ImportError: Module "api.utils" does not define a "custom_exception_handler" attribute/class.
[2025-05-04 18:32:20,770] ERROR log 17740 12456 Internal Server Error: /api/profile/3
[2025-05-04 18:32:21,210] ERROR log 17740 12456 Internal Server Error: /api/users/following/status/3
Traceback (most recent call last):
  File "C:\Users\aleja\Desktop\BINFO\TFB\Myqx\Myqx-bff\api\controllers\users_controller.py", line 600, in check_following
    print(f"[USERS_CONTROLLER] Verificando relación de seguimiento entre {follower_id} y {followed_id}", file=sys.stderr)
                                                                                                              ^^^
NameError: name 'sys' is not defined. Did you forget to import 'sys'?

During handling of the above exception, another exception occurred:

Traceback (most recent call last):
  File "C:\Users\aleja\Desktop\BINFO\TFB\Myqx\Myqx-bff\venv\Lib\site-packages\rest_framework\views.py", line 512, in dispatch
    response = handler(request, *args, **kwargs)
  File "C:\Users\aleja\Desktop\BINFO\TFB\Myqx\Myqx-bff\api\views\user_views.py", line 126, in get
    return self.users_controller.check_following(follower_id, followed_id)
           ~~~~~~~~~~~~~~~~~~~~~~~~~~~~~~~~~~~~~^^^^^^^^^^^^^^^^^^^^^^^^^^
  File "C:\Users\aleja\Desktop\BINFO\TFB\Myqx\Myqx-bff\api\controllers\users_controller.py", line 637, in check_following
    print(f"[USERS_CONTROLLER] Error verificando relación de seguimiento: {str(e)}", file=sys.stderr)
                                                                                          ^^^
NameError: name 'sys' is not defined. Did you forget to import 'sys'?

During handling of the above exception, another exception occurred:

Traceback (most recent call last):
  File "C:\Users\aleja\Desktop\BINFO\TFB\Myqx\Myqx-bff\venv\Lib\site-packages\django\utils\module_loading.py", line 30, in import_string
    return cached_import(module_path, class_name)
  File "C:\Users\aleja\Desktop\BINFO\TFB\Myqx\Myqx-bff\venv\Lib\site-packages\django\utils\module_loading.py", line 16, in cached_import
    return getattr(module, class_name)
AttributeError: module 'api.utils' has no attribute 'custom_exception_handler'

The above exception was the direct cause of the following exception:

Traceback (most recent call last):
  File "C:\Users\aleja\Desktop\BINFO\TFB\Myqx\Myqx-bff\venv\Lib\site-packages\rest_framework\settings.py", line 179, in import_from_string
    return import_string(val)
  File "C:\Users\aleja\Desktop\BINFO\TFB\Myqx\Myqx-bff\venv\Lib\site-packages\django\utils\module_loading.py", line 32, in import_string
    raise ImportError(
    ...<2 lines>...
    ) from err
ImportError: Module "api.utils" does not define a "custom_exception_handler" attribute/class

During handling of the above exception, another exception occurred:

Traceback (most recent call last):
  File "C:\Users\aleja\Desktop\BINFO\TFB\Myqx\Myqx-bff\venv\Lib\site-packages\django\core\handlers\exception.py", line 55, in inner
    response = get_response(request)
  File "C:\Users\aleja\Desktop\BINFO\TFB\Myqx\Myqx-bff\venv\Lib\site-packages\django\core\handlers\base.py", line 197, in _get_response
    response = wrapped_callback(request, *callback_args, **callback_kwargs)
  File "C:\Users\aleja\Desktop\BINFO\TFB\Myqx\Myqx-bff\venv\Lib\site-packages\django\views\decorators\csrf.py", line 65, in _view_wrapper
    return view_func(request, *args, **kwargs)
  File "C:\Users\aleja\Desktop\BINFO\TFB\Myqx\Myqx-bff\venv\Lib\site-packages\django\views\generic\base.py", line 104, in view
    return self.dispatch(request, *args, **kwargs)
           ~~~~~~~~~~~~~^^^^^^^^^^^^^^^^^^^^^^^^^^
  File "C:\Users\aleja\Desktop\BINFO\TFB\Myqx\Myqx-bff\venv\Lib\site-packages\rest_framework\views.py", line 515, in dispatch
    response = self.handle_exception(exc)
  File "C:\Users\aleja\Desktop\BINFO\TFB\Myqx\Myqx-bff\venv\Lib\site-packages\rest_framework\views.py", line 469, in handle_exception
    exception_handler = self.get_exception_handler()
  File "C:\Users\aleja\Desktop\BINFO\TFB\Myqx\Myqx-bff\venv\Lib\site-packages\rest_framework\views.py", line 304, in get_exception_handler
    return self.settings.EXCEPTION_HANDLER
           ^^^^^^^^^^^^^^^^^^^^^^^^^^^^^^^
  File "C:\Users\aleja\Desktop\BINFO\TFB\Myqx\Myqx-bff\venv\Lib\site-packages\rest_framework\settings.py", line 227, in __getattr__
    val = perform_import(val, attr)
  File "C:\Users\aleja\Desktop\BINFO\TFB\Myqx\Myqx-bff\venv\Lib\site-packages\rest_framework\settings.py", line 168, in perform_import
    return import_from_string(val, setting_name)
  File "C:\Users\aleja\Desktop\BINFO\TFB\Myqx\Myqx-bff\venv\Lib\site-packages\rest_framework\settings.py", line 182, in import_from_string
    raise ImportError(msg)
ImportError: Could not import 'api.utils.custom_exception_handler' for API setting 'EXCEPTION_HANDLER'. ImportError: Module "api.utils" does not define a "custom_exception_handler" attribute/class.
[2025-05-04 18:48:04,031] ERROR log 6460 19944 Internal Server Error: /api/users/following/status/3
[2025-05-04 19:24:06,585] ERROR log 1920 17652 Internal Server Error: /api/auth/verify
[2025-05-04 19:24:06,688] ERROR log 1920 17652 Internal Server Error: /api/auth/verify
[2025-05-04 19:24:06,817] ERROR log 1920 17652 Internal Server Error: /api/auth/verify
[2025-05-04 19:26:46,698] ERROR log 1920 3176 Internal Server Error: /api/feed
[2025-05-04 19:26:51,037] ERROR log 1920 3176 Internal Server Error: /api/feed
[2025-05-04 19:29:27,568] ERROR log 15212 27556 Internal Server Error: /api/users/following/status/4/3
[2025-05-04 19:29:39,844] ERROR log 15212 23160 Internal Server Error: /api/feed
[2025-05-04 19:29:47,510] ERROR log 15212 23160 Internal Server Error: /api/feed
[2025-05-04 19:29:52,883] ERROR log 15212 23160 Internal Server Error: /api/feed
[2025-05-04 19:31:15,435] ERROR log 13248 1900 Internal Server Error: /api/users/following/status/4/3
[2025-05-04 19:32:53,263] ERROR log 13248 16488 Internal Server Error: /api/users/following/status/4/3
[2025-05-04 19:45:03,865] ERROR log 13248 1648 Internal Server Error: /api/users/following/status/4/3
[2025-05-04 19:45:17,682] ERROR log 13248 7976 Internal Server Error: /api/users/following/status/4/3
[2025-05-04 19:48:48,651] ERROR log 13248 15312 Internal Server Error: /api/users/following/status/4/3
[2025-05-04 19:51:02,923] ERROR log 13248 26660 Internal Server Error: /api/users/following/status/4/3
[2025-05-04 19:51:26,005] ERROR log 13248 16536 Internal Server Error: /api/users/following/status/4/3
[2025-05-04 20:24:24,568] ERROR log 13248 16744 Internal Server Error: /api/users/following/status/4/3
[2025-05-04 20:25:45,491] ERROR log 13248 17708 Internal Server Error: /api/users/following/status/4/3
[2025-05-04 20:26:32,674] ERROR log 13248 14356 Internal Server Error: /api/users/following/status/4/3
[2025-05-04 22:23:02,364] ERROR log 13248 24836 Internal Server Error: /api/users/following/status/4/3
[2025-05-04 22:35:51,569] ERROR log 13248 4032 Internal Server Error: /api/users/following/status/4/3
[2025-05-04 22:43:50,388] ERROR log 13248 26084 Internal Server Error: /api/users/following/status/4/3
[2025-05-04 22:51:20,192] ERROR log 13248 23664 Internal Server Error: /api/users/following/status/4/3
[2025-05-04 22:58:36,453] ERROR log 13248 19896 Internal Server Error: /api/users/following/status/4/3
[2025-05-04 23:03:06,899] ERROR log 13248 26012 Internal Server Error: /api/auth/verify
[2025-05-04 23:03:06,997] ERROR log 13248 26012 Internal Server Error: /api/auth/verify
[2025-05-04 23:03:07,172] ERROR log 13248 26012 Internal Server Error: /api/auth/verify
[2025-05-04 23:03:43,540] ERROR log 13248 15552 Internal Server Error: /api/users/following/status/4/3
[2025-05-04 23:06:54,365] ERROR log 13248 17536 Internal Server Error: /api/users/following/status/4/3
[2025-05-04 23:08:01,529] ERROR log 13248 9428 Internal Server Error: /api/users/following/status/4/3
[2025-05-04 23:29:26,502] ERROR log 13248 19164 Internal Server Error: /api/users/following/status/4/3
[2025-05-04 23:31:44,353] ERROR log 13248 4080 Internal Server Error: /api/users/following/status/4/3
