[2025-05-04 17:41:19,719] ERROR log 27812 15524 Internal Server Error: /api/profile/3
[2025-05-04 17:41:20,136] ERROR log 27812 15524 Internal Server Error: /api/users/following/status/3
Traceback (most recent call last):
  File "C:\Users\aleja\Desktop\BINFO\TFB\Myqx\Myqx-bff\venv\Lib\site-packages\rest_framework\views.py", line 512, in dispatch
    response = handler(request, *args, **kwargs)
  File "C:\Users\aleja\Desktop\BINFO\TFB\Myqx\Myqx-bff\api\views\user_views.py", line 126, in get
    return self.users_controller.check_following(follower_id, followed_id)
           ^^^^^^^^^^^^^^^^^^^^^^^^^^^^^^^^^^^^^
AttributeError: 'UsersController' object has no attribute 'check_following'

During handling of the above exception, another exception occurred:

Traceback (most recent call last):
  File "C:\Users\aleja\Desktop\BINFO\TFB\Myqx\Myqx-bff\venv\Lib\site-packages\django\utils\module_loading.py", line 30, in import_string
    return cached_import(module_path, class_name)
  File "C:\Users\aleja\Desktop\BINFO\TFB\Myqx\Myqx-bff\venv\Lib\site-packages\django\utils\module_loading.py", line 16, in cached_import
    return getattr(module, class_name)
AttributeError: module 'api.utils' has no attribute 'custom_exception_handler'

The above exception was the direct cause of the following exception:

Traceback (most recent call last):
  File "C:\Users\aleja\Desktop\BINFO\TFB\Myqx\Myqx-bff\venv\Lib\site-packages\rest_framework\settings.py", line 179, in import_from_string
    return import_string(val)
  File "C:\Users\aleja\Desktop\BINFO\TFB\Myqx\Myqx-bff\venv\Lib\site-packages\django\utils\module_loading.py", line 32, in import_string
    raise ImportError(
    ...<2 lines>...
    ) from err
ImportError: Module "api.utils" does not define a "custom_exception_handler" attribute/class

During handling of the above exception, another exception occurred:

Traceback (most recent call last):
  File "C:\Users\aleja\Desktop\BINFO\TFB\Myqx\Myqx-bff\venv\Lib\site-packages\django\core\handlers\exception.py", line 55, in inner
    response = get_response(request)
  File "C:\Users\aleja\Desktop\BINFO\TFB\Myqx\Myqx-bff\venv\Lib\site-packages\django\core\handlers\base.py", line 197, in _get_response
    response = wrapped_callback(request, *callback_args, **callback_kwargs)
  File "C:\Users\aleja\Desktop\BINFO\TFB\Myqx\Myqx-bff\venv\Lib\site-packages\django\views\decorators\csrf.py", line 65, in _view_wrapper
    return view_func(request, *args, **kwargs)
  File "C:\Users\aleja\Desktop\BINFO\TFB\Myqx\Myqx-bff\venv\Lib\site-packages\django\views\generic\base.py", line 104, in view
    return self.dispatch(request, *args, **kwargs)
           ~~~~~~~~~~~~~^^^^^^^^^^^^^^^^^^^^^^^^^^
  File "C:\Users\aleja\Desktop\BINFO\TFB\Myqx\Myqx-bff\venv\Lib\site-packages\rest_framework\views.py", line 515, in dispatch
    response = self.handle_exception(exc)
  File "C:\Users\aleja\Desktop\BINFO\TFB\Myqx\Myqx-bff\venv\Lib\site-packages\rest_framework\views.py", line 469, in handle_exception
    exception_handler = self.get_exception_handler()
  File "C:\Users\aleja\Desktop\BINFO\TFB\Myqx\Myqx-bff\venv\Lib\site-packages\rest_framework\views.py", line 304, in get_exception_handler
    return self.settings.EXCEPTION_HANDLER
           ^^^^^^^^^^^^^^^^^^^^^^^^^^^^^^^
  File "C:\Users\aleja\Desktop\BINFO\TFB\Myqx\Myqx-bff\venv\Lib\site-packages\rest_framework\settings.py", line 227, in __getattr__
    val = perform_import(val, attr)
  File "C:\Users\aleja\Desktop\BINFO\TFB\Myqx\Myqx-bff\venv\Lib\site-packages\rest_framework\settings.py", line 168, in perform_import
    return import_from_string(val, setting_name)
  File "C:\Users\aleja\Desktop\BINFO\TFB\Myqx\Myqx-bff\venv\Lib\site-packages\rest_framework\settings.py", line 182, in import_from_string
    raise ImportError(msg)
ImportError: Could not import 'api.utils.custom_exception_handler' for API setting 'EXCEPTION_HANDLER'. ImportError: Module "api.utils" does not define a "custom_exception_handler" attribute/class.
[2025-05-04 17:41:54,388] ERROR log 27812 5372 Internal Server Error: /api/profile/3
[2025-05-04 17:41:54,632] ERROR log 27812 5372 Internal Server Error: /api/users/following/status/3
Traceback (most recent call last):
  File "C:\Users\aleja\Desktop\BINFO\TFB\Myqx\Myqx-bff\venv\Lib\site-packages\rest_framework\views.py", line 512, in dispatch
    response = handler(request, *args, **kwargs)
  File "C:\Users\aleja\Desktop\BINFO\TFB\Myqx\Myqx-bff\api\views\user_views.py", line 126, in get
    return self.users_controller.check_following(follower_id, followed_id)
           ^^^^^^^^^^^^^^^^^^^^^^^^^^^^^^^^^^^^^
AttributeError: 'UsersController' object has no attribute 'check_following'

During handling of the above exception, another exception occurred:

Traceback (most recent call last):
  File "C:\Users\aleja\Desktop\BINFO\TFB\Myqx\Myqx-bff\venv\Lib\site-packages\django\utils\module_loading.py", line 30, in import_string
    return cached_import(module_path, class_name)
  File "C:\Users\aleja\Desktop\BINFO\TFB\Myqx\Myqx-bff\venv\Lib\site-packages\django\utils\module_loading.py", line 16, in cached_import
    return getattr(module, class_name)
AttributeError: module 'api.utils' has no attribute 'custom_exception_handler'

The above exception was the direct cause of the following exception:

Traceback (most recent call last):
  File "C:\Users\aleja\Desktop\BINFO\TFB\Myqx\Myqx-bff\venv\Lib\site-packages\rest_framework\settings.py", line 179, in import_from_string
    return import_string(val)
  File "C:\Users\aleja\Desktop\BINFO\TFB\Myqx\Myqx-bff\venv\Lib\site-packages\django\utils\module_loading.py", line 32, in import_string
    raise ImportError(
    ...<2 lines>...
    ) from err
ImportError: Module "api.utils" does not define a "custom_exception_handler" attribute/class

During handling of the above exception, another exception occurred:

Traceback (most recent call last):
  File "C:\Users\aleja\Desktop\BINFO\TFB\Myqx\Myqx-bff\venv\Lib\site-packages\django\core\handlers\exception.py", line 55, in inner
    response = get_response(request)
  File "C:\Users\aleja\Desktop\BINFO\TFB\Myqx\Myqx-bff\venv\Lib\site-packages\django\core\handlers\base.py", line 197, in _get_response
    response = wrapped_callback(request, *callback_args, **callback_kwargs)
  File "C:\Users\aleja\Desktop\BINFO\TFB\Myqx\Myqx-bff\venv\Lib\site-packages\django\views\decorators\csrf.py", line 65, in _view_wrapper
    return view_func(request, *args, **kwargs)
  File "C:\Users\aleja\Desktop\BINFO\TFB\Myqx\Myqx-bff\venv\Lib\site-packages\django\views\generic\base.py", line 104, in view
    return self.dispatch(request, *args, **kwargs)
           ~~~~~~~~~~~~~^^^^^^^^^^^^^^^^^^^^^^^^^^
  File "C:\Users\aleja\Desktop\BINFO\TFB\Myqx\Myqx-bff\venv\Lib\site-packages\rest_framework\views.py", line 515, in dispatch
    response = self.handle_exception(exc)
  File "C:\Users\aleja\Desktop\BINFO\TFB\Myqx\Myqx-bff\venv\Lib\site-packages\rest_framework\views.py", line 469, in handle_exception
    exception_handler = self.get_exception_handler()
  File "C:\Users\aleja\Desktop\BINFO\TFB\Myqx\Myqx-bff\venv\Lib\site-packages\rest_framework\views.py", line 304, in get_exception_handler
    return self.settings.EXCEPTION_HANDLER
           ^^^^^^^^^^^^^^^^^^^^^^^^^^^^^^^
  File "C:\Users\aleja\Desktop\BINFO\TFB\Myqx\Myqx-bff\venv\Lib\site-packages\rest_framework\settings.py", line 227, in __getattr__
    val = perform_import(val, attr)
  File "C:\Users\aleja\Desktop\BINFO\TFB\Myqx\Myqx-bff\venv\Lib\site-packages\rest_framework\settings.py", line 168, in perform_import
    return import_from_string(val, setting_name)
  File "C:\Users\aleja\Desktop\BINFO\TFB\Myqx\Myqx-bff\venv\Lib\site-packages\rest_framework\settings.py", line 182, in import_from_string
    raise ImportError(msg)
ImportError: Could not import 'api.utils.custom_exception_handler' for API setting 'EXCEPTION_HANDLER'. ImportError: Module "api.utils" does not define a "custom_exception_handler" attribute/class.
[2025-05-04 18:32:20,770] ERROR log 17740 12456 Internal Server Error: /api/profile/3
[2025-05-04 18:32:21,210] ERROR log 17740 12456 Internal Server Error: /api/users/following/status/3
Traceback (most recent call last):
  File "C:\Users\aleja\Desktop\BINFO\TFB\Myqx\Myqx-bff\api\controllers\users_controller.py", line 600, in check_following
    print(f"[USERS_CONTROLLER] Verificando relación de seguimiento entre {follower_id} y {followed_id}", file=sys.stderr)
                                                                                                              ^^^
NameError: name 'sys' is not defined. Did you forget to import 'sys'?

During handling of the above exception, another exception occurred:

Traceback (most recent call last):
  File "C:\Users\aleja\Desktop\BINFO\TFB\Myqx\Myqx-bff\venv\Lib\site-packages\rest_framework\views.py", line 512, in dispatch
    response = handler(request, *args, **kwargs)
  File "C:\Users\aleja\Desktop\BINFO\TFB\Myqx\Myqx-bff\api\views\user_views.py", line 126, in get
    return self.users_controller.check_following(follower_id, followed_id)
           ~~~~~~~~~~~~~~~~~~~~~~~~~~~~~~~~~~~~~^^^^^^^^^^^^^^^^^^^^^^^^^^
  File "C:\Users\aleja\Desktop\BINFO\TFB\Myqx\Myqx-bff\api\controllers\users_controller.py", line 637, in check_following
    print(f"[USERS_CONTROLLER] Error verificando relación de seguimiento: {str(e)}", file=sys.stderr)
                                                                                          ^^^
NameError: name 'sys' is not defined. Did you forget to import 'sys'?

During handling of the above exception, another exception occurred:

Traceback (most recent call last):
  File "C:\Users\aleja\Desktop\BINFO\TFB\Myqx\Myqx-bff\venv\Lib\site-packages\django\utils\module_loading.py", line 30, in import_string
    return cached_import(module_path, class_name)
  File "C:\Users\aleja\Desktop\BINFO\TFB\Myqx\Myqx-bff\venv\Lib\site-packages\django\utils\module_loading.py", line 16, in cached_import
    return getattr(module, class_name)
AttributeError: module 'api.utils' has no attribute 'custom_exception_handler'

The above exception was the direct cause of the following exception:

Traceback (most recent call last):
  File "C:\Users\aleja\Desktop\BINFO\TFB\Myqx\Myqx-bff\venv\Lib\site-packages\rest_framework\settings.py", line 179, in import_from_string
    return import_string(val)
  File "C:\Users\aleja\Desktop\BINFO\TFB\Myqx\Myqx-bff\venv\Lib\site-packages\django\utils\module_loading.py", line 32, in import_string
    raise ImportError(
    ...<2 lines>...
    ) from err
ImportError: Module "api.utils" does not define a "custom_exception_handler" attribute/class

During handling of the above exception, another exception occurred:

Traceback (most recent call last):
  File "C:\Users\aleja\Desktop\BINFO\TFB\Myqx\Myqx-bff\venv\Lib\site-packages\django\core\handlers\exception.py", line 55, in inner
    response = get_response(request)
  File "C:\Users\aleja\Desktop\BINFO\TFB\Myqx\Myqx-bff\venv\Lib\site-packages\django\core\handlers\base.py", line 197, in _get_response
    response = wrapped_callback(request, *callback_args, **callback_kwargs)
  File "C:\Users\aleja\Desktop\BINFO\TFB\Myqx\Myqx-bff\venv\Lib\site-packages\django\views\decorators\csrf.py", line 65, in _view_wrapper
    return view_func(request, *args, **kwargs)
  File "C:\Users\aleja\Desktop\BINFO\TFB\Myqx\Myqx-bff\venv\Lib\site-packages\django\views\generic\base.py", line 104, in view
    return self.dispatch(request, *args, **kwargs)
           ~~~~~~~~~~~~~^^^^^^^^^^^^^^^^^^^^^^^^^^
  File "C:\Users\aleja\Desktop\BINFO\TFB\Myqx\Myqx-bff\venv\Lib\site-packages\rest_framework\views.py", line 515, in dispatch
    response = self.handle_exception(exc)
  File "C:\Users\aleja\Desktop\BINFO\TFB\Myqx\Myqx-bff\venv\Lib\site-packages\rest_framework\views.py", line 469, in handle_exception
    exception_handler = self.get_exception_handler()
  File "C:\Users\aleja\Desktop\BINFO\TFB\Myqx\Myqx-bff\venv\Lib\site-packages\rest_framework\views.py", line 304, in get_exception_handler
    return self.settings.EXCEPTION_HANDLER
           ^^^^^^^^^^^^^^^^^^^^^^^^^^^^^^^
  File "C:\Users\aleja\Desktop\BINFO\TFB\Myqx\Myqx-bff\venv\Lib\site-packages\rest_framework\settings.py", line 227, in __getattr__
    val = perform_import(val, attr)
  File "C:\Users\aleja\Desktop\BINFO\TFB\Myqx\Myqx-bff\venv\Lib\site-packages\rest_framework\settings.py", line 168, in perform_import
    return import_from_string(val, setting_name)
  File "C:\Users\aleja\Desktop\BINFO\TFB\Myqx\Myqx-bff\venv\Lib\site-packages\rest_framework\settings.py", line 182, in import_from_string
    raise ImportError(msg)
ImportError: Could not import 'api.utils.custom_exception_handler' for API setting 'EXCEPTION_HANDLER'. ImportError: Module "api.utils" does not define a "custom_exception_handler" attribute/class.
[2025-05-04 18:48:04,031] ERROR log 6460 19944 Internal Server Error: /api/users/following/status/3
[2025-05-04 19:24:06,585] ERROR log 1920 17652 Internal Server Error: /api/auth/verify
[2025-05-04 19:24:06,688] ERROR log 1920 17652 Internal Server Error: /api/auth/verify
[2025-05-04 19:24:06,817] ERROR log 1920 17652 Internal Server Error: /api/auth/verify
[2025-05-04 19:26:46,698] ERROR log 1920 3176 Internal Server Error: /api/feed
[2025-05-04 19:26:51,037] ERROR log 1920 3176 Internal Server Error: /api/feed
[2025-05-04 19:29:27,568] ERROR log 15212 27556 Internal Server Error: /api/users/following/status/4/3
[2025-05-04 19:29:39,844] ERROR log 15212 23160 Internal Server Error: /api/feed
[2025-05-04 19:29:47,510] ERROR log 15212 23160 Internal Server Error: /api/feed
[2025-05-04 19:29:52,883] ERROR log 15212 23160 Internal Server Error: /api/feed
[2025-05-04 19:31:15,435] ERROR log 13248 1900 Internal Server Error: /api/users/following/status/4/3
[2025-05-04 19:32:53,263] ERROR log 13248 16488 Internal Server Error: /api/users/following/status/4/3
[2025-05-04 19:45:03,865] ERROR log 13248 1648 Internal Server Error: /api/users/following/status/4/3
[2025-05-04 19:45:17,682] ERROR log 13248 7976 Internal Server Error: /api/users/following/status/4/3
[2025-05-04 19:48:48,651] ERROR log 13248 15312 Internal Server Error: /api/users/following/status/4/3
[2025-05-04 19:51:02,923] ERROR log 13248 26660 Internal Server Error: /api/users/following/status/4/3
[2025-05-04 19:51:26,005] ERROR log 13248 16536 Internal Server Error: /api/users/following/status/4/3
[2025-05-04 20:24:24,568] ERROR log 13248 16744 Internal Server Error: /api/users/following/status/4/3
[2025-05-04 20:25:45,491] ERROR log 13248 17708 Internal Server Error: /api/users/following/status/4/3
[2025-05-04 20:26:32,674] ERROR log 13248 14356 Internal Server Error: /api/users/following/status/4/3
[2025-05-04 22:23:02,364] ERROR log 13248 24836 Internal Server Error: /api/users/following/status/4/3
[2025-05-04 22:35:51,569] ERROR log 13248 4032 Internal Server Error: /api/users/following/status/4/3
[2025-05-04 22:43:50,388] ERROR log 13248 26084 Internal Server Error: /api/users/following/status/4/3
[2025-05-04 22:51:20,192] ERROR log 13248 23664 Internal Server Error: /api/users/following/status/4/3
[2025-05-04 22:58:36,453] ERROR log 13248 19896 Internal Server Error: /api/users/following/status/4/3
[2025-05-04 23:03:06,899] ERROR log 13248 26012 Internal Server Error: /api/auth/verify
[2025-05-04 23:03:06,997] ERROR log 13248 26012 Internal Server Error: /api/auth/verify
[2025-05-04 23:03:07,172] ERROR log 13248 26012 Internal Server Error: /api/auth/verify
[2025-05-04 23:03:43,540] ERROR log 13248 15552 Internal Server Error: /api/users/following/status/4/3
[2025-05-04 23:06:54,365] ERROR log 13248 17536 Internal Server Error: /api/users/following/status/4/3
[2025-05-04 23:08:01,529] ERROR log 13248 9428 Internal Server Error: /api/users/following/status/4/3
[2025-05-04 23:29:26,502] ERROR log 13248 19164 Internal Server Error: /api/users/following/status/4/3
[2025-05-04 23:31:44,353] ERROR log 13248 4080 Internal Server Error: /api/users/following/status/4/3
[2025-05-04 23:37:14,182] ERROR log 16136 18916 Internal Server Error: /api/users/following/status/4/3
[2025-05-15 17:08:53,469] ERROR log 10624 5476 Internal Server Error: /api/auth/verify
[2025-05-15 17:08:53,556] ERROR log 10624 15004 Internal Server Error: /api/auth/verify
[2025-05-15 17:08:54,042] ERROR log 10624 15004 Internal Server Error: /api/auth/verify
[2025-05-15 17:48:41,042] ERROR log 10624 4028 Internal Server Error: /api/auth/verify
[2025-05-15 18:35:48,263] ERROR log 10624 18064 Internal Server Error: /api/auth/verify
[2025-05-15 18:35:48,346] ERROR log 10624 18064 Internal Server Error: /api/auth/verify
[2025-05-15 18:35:48,452] ERROR log 10624 18064 Internal Server Error: /api/auth/verify
[2025-05-15 19:00:18,338] ERROR log 23172 7416 Internal Server Error: /api/auth/verify
[2025-05-15 19:00:18,451] ERROR log 23172 7416 Internal Server Error: /api/auth/verify
[2025-05-15 19:00:18,552] ERROR log 23172 7416 Internal Server Error: /api/auth/verify
[2025-05-15 22:07:59,483] ERROR log 23172 29272 Internal Server Error: /api/auth/verify
[2025-05-15 22:07:59,567] ERROR log 23172 29272 Internal Server Error: /api/auth/verify
[2025-05-15 22:07:59,692] ERROR log 23172 29272 Internal Server Error: /api/auth/verify
[2025-05-15 22:12:21,121] ERROR log 23172 9116 Internal Server Error: /api/auth/verify
[2025-05-15 22:12:41,450] ERROR log 23172 13824 Internal Server Error: /api/auth/verify
[2025-05-15 22:13:21,875] ERROR log 23172 25656 Internal Server Error: /api/auth/verify
[2025-05-15 22:13:21,958] ERROR log 23172 25656 Internal Server Error: /api/auth/verify
[2025-05-15 22:13:22,091] ERROR log 23172 25656 Internal Server Error: /api/auth/verify
[2025-05-15 22:16:30,625] ERROR log 23172 21632 Internal Server Error: /api/auth/verify
[2025-05-15 22:18:20,404] ERROR log 23172 28388 Internal Server Error: /api/users/following/status/3/4
[2025-05-15 22:20:11,961] ERROR log 23172 12648 Internal Server Error: /api/auth/verify
[2025-05-15 22:20:12,045] ERROR log 23172 12648 Internal Server Error: /api/auth/verify
[2025-05-15 22:20:12,164] ERROR log 23172 12648 Internal Server Error: /api/auth/verify
[2025-05-15 22:20:57,512] ERROR log 23172 23460 Internal Server Error: /api/users/following/status/3/4
[2025-05-15 22:24:14,637] ERROR log 23172 20440 Internal Server Error: /api/users/following/status/3/4
[2025-05-15 22:26:04,745] ERROR log 23172 2772 Internal Server Error: /api/auth/verify
[2025-05-15 22:26:04,816] ERROR log 23172 15116 Internal Server Error: /api/auth/verify
[2025-05-15 22:26:05,024] ERROR log 23172 15116 Internal Server Error: /api/auth/verify
[2025-05-15 22:28:48,709] ERROR log 23172 17540 Internal Server Error: /api/users/following/status/4/3
[2025-05-15 22:28:55,892] ERROR log 23172 3968 Internal Server Error: /api/users/following/status/4/3
[2025-05-15 22:29:20,605] ERROR log 23172 27280 Internal Server Error: /api/auth/verify
[2025-05-15 22:29:20,665] ERROR log 23172 27280 Internal Server Error: /api/auth/verify
[2025-05-15 22:29:20,736] ERROR log 23172 27280 Internal Server Error: /api/auth/verify
[2025-05-15 22:31:50,531] ERROR log 23172 27664 Internal Server Error: /api/users/following/status/4/3
[2025-05-15 22:32:02,151] ERROR log 23172 20200 Internal Server Error: /api/users/following/status/4/3
[2025-05-15 22:49:39,855] ERROR log 23172 28684 Internal Server Error: /api/users/following/status/3/4
[2025-05-15 22:58:08,172] ERROR log 23172 6608 Internal Server Error: /api/users/following/status/3/4
[2025-05-15 23:01:04,421] ERROR log 23172 28112 Internal Server Error: /api/users/following/status/3/4
[2025-05-15 23:13:25,887] ERROR log 23172 11036 Internal Server Error: /api/users/following/status/3/4
[2025-05-15 23:14:09,029] ERROR log 23172 23436 Internal Server Error: /api/users/following/status/3/4
[2025-05-15 23:36:50,178] ERROR log 23172 20568 Internal Server Error: /api/auth/verify
[2025-05-15 23:36:57,849] ERROR log 23172 21256 Internal Server Error: /api/profile/3
[2025-05-15 23:37:19,145] ERROR log 23172 26644 Internal Server Error: /api/auth/verify
[2025-05-15 23:37:21,736] ERROR log 23172 14132 Internal Server Error: /api/profile/3
[2025-05-15 23:37:42,102] ERROR log 23172 11472 Internal Server Error: /api/profile/3
[2025-05-15 23:37:50,889] ERROR log 23172 28320 Internal Server Error: /api/profile/3
[2025-05-15 23:38:59,624] ERROR log 23172 21256 Internal Server Error: /api/auth/verify
[2025-05-15 23:39:14,365] ERROR log 23172 21256 Internal Server Error: /api/auth/verify
[2025-05-15 23:39:24,805] ERROR log 23172 21256 Internal Server Error: /api/auth/verify
[2025-05-15 23:40:47,218] ERROR log 23172 4588 Internal Server Error: /api/auth/verify
[2025-05-15 23:41:36,056] ERROR log 23172 17504 Internal Server Error: /api/auth/verify
[2025-05-15 23:42:34,921] ERROR log 23172 29004 Internal Server Error: /api/auth/verify
[2025-05-15 23:42:41,047] ERROR log 23172 29004 Internal Server Error: /api/auth/verify
[2025-05-15 23:45:59,286] ERROR log 23172 8652 Internal Server Error: /api/auth/verify
[2025-05-15 23:47:57,342] ERROR log 23172 21876 Internal Server Error: /api/auth/verify
[2025-05-15 23:50:49,588] ERROR log 23172 13388 Internal Server Error: /api/auth/verify
[2025-05-15 23:51:55,549] ERROR log 23172 4932 Internal Server Error: /api/auth/verify
[2025-05-16 00:10:18,828] ERROR log 23172 18484 Internal Server Error: /api/users/following/status/3/4
[2025-05-16 00:10:28,173] ERROR log 23172 9708 Internal Server Error: /api/users/following/status/3/4
[2025-05-16 00:16:46,666] ERROR log 23172 18920 Internal Server Error: /api/users/following/status/3/4
[2025-05-16 00:33:03,168] ERROR log 25464 28952 Internal Server Error: /api/users/following/status/3/4
[2025-05-16 00:33:18,573] ERROR log 25464 26316 Internal Server Error: /api/users/following/status/3/4
[2025-05-16 00:33:30,969] ERROR log 25464 7124 Internal Server Error: /api/profile/3
[2025-05-16 00:33:34,071] ERROR log 25464 26936 Internal Server Error: /api/users/following/status/3/4
[2025-05-16 00:33:38,168] ERROR log 25464 5080 Internal Server Error: /api/users/following/status/3/4
[2025-05-16 00:33:53,590] ERROR log 25464 28332 Internal Server Error: /api/users/following/status/3/4
[2025-05-16 00:34:02,930] ERROR log 25464 1888 Internal Server Error: /api/users/following/status/3/4
[2025-05-16 00:34:09,022] ERROR log 25464 26540 Internal Server Error: /api/users/following/status/3/4
[2025-05-16 00:34:18,355] ERROR log 25464 7832 Internal Server Error: /api/users/following/status/3/4
[2025-05-16 00:34:33,823] ERROR log 25464 17132 Internal Server Error: /api/users/following/status/3/4
[2025-05-16 00:34:36,573] ERROR log 25464 26680 Internal Server Error: /api/profile/4
[2025-05-16 00:34:36,791] ERROR log 25464 19884 Internal Server Error: /api/users/following/status/3/4
[2025-05-16 00:34:52,185] ERROR log 25464 16560 Internal Server Error: /api/users/following/status/3/4
[2025-05-16 00:35:07,650] ERROR log 25464 24164 Internal Server Error: /api/users/following/status/3/4
[2025-05-16 00:35:24,178] ERROR log 25464 25772 Internal Server Error: /api/auth/verify
[2025-05-16 00:35:24,233] ERROR log 25464 25772 Internal Server Error: /api/auth/verify
[2025-05-16 00:35:24,321] ERROR log 25464 25772 Internal Server Error: /api/auth/verify
[2025-05-16 00:36:34,987] ERROR log 25464 24044 Internal Server Error: /api/auth/verify
[2025-05-16 00:36:35,071] ERROR log 25464 24044 Internal Server Error: /api/auth/verify
[2025-05-16 00:36:35,208] ERROR log 25464 24044 Internal Server Error: /api/auth/verify
[2025-05-16 17:20:15,855] ERROR log 8684 5484 Internal Server Error: /api/auth/verify
[2025-05-16 17:20:15,901] ERROR log 8684 5484 Internal Server Error: /api/auth/verify
[2025-05-16 17:20:16,002] ERROR log 8684 5484 Internal Server Error: /api/auth/verify
[2025-05-16 18:01:53,483] ERROR log 8684 24400 Internal Server Error: /api/auth/verify
[2025-05-16 18:01:53,519] ERROR log 8684 24400 Internal Server Error: /api/auth/verify
[2025-05-16 18:01:53,628] ERROR log 8684 24400 Internal Server Error: /api/auth/verify
[2025-05-16 18:03:59,370] ERROR log 8684 17636 Internal Server Error: /api/auth/verify
[2025-05-16 18:03:59,429] ERROR log 8684 17636 Internal Server Error: /api/auth/verify
[2025-05-16 18:03:59,516] ERROR log 8684 17636 Internal Server Error: /api/auth/verify
[2025-05-16 18:07:10,493] ERROR log 8684 23788 Internal Server Error: /api/auth/verify
[2025-05-16 18:07:10,545] ERROR log 8684 23788 Internal Server Error: /api/auth/verify
[2025-05-16 18:07:10,654] ERROR log 8684 23788 Internal Server Error: /api/auth/verify
[2025-05-16 18:20:54,330] ERROR log 8684 16904 Internal Server Error: /api/auth/verify
[2025-05-16 18:20:54,332] ERROR log 8684 23888 Internal Server Error: /api/auth/verify
[2025-05-16 18:20:54,454] ERROR log 8684 23888 Internal Server Error: /api/auth/verify
[2025-05-16 18:24:00,502] ERROR log 8684 24172 Internal Server Error: /api/auth/verify
[2025-05-16 18:24:00,551] ERROR log 8684 24172 Internal Server Error: /api/auth/verify
[2025-05-16 18:24:00,650] ERROR log 8684 24172 Internal Server Error: /api/auth/verify
[2025-05-16 19:13:27,347] ERROR log 8684 23692 Internal Server Error: /api/auth/verify
[2025-05-16 19:13:27,396] ERROR log 8684 23692 Internal Server Error: /api/auth/verify
[2025-05-16 19:13:27,473] ERROR log 8684 23692 Internal Server Error: /api/auth/verify
[2025-05-16 19:38:23,098] ERROR log 8684 21816 Internal Server Error: /api/auth/verify
[2025-05-16 19:38:23,210] ERROR log 8684 21816 Internal Server Error: /api/auth/verify
[2025-05-16 19:38:23,315] ERROR log 8684 21816 Internal Server Error: /api/auth/verify
[2025-05-16 19:46:30,641] ERROR log 8684 13568 Internal Server Error: /api/auth/verify
[2025-05-16 19:46:30,752] ERROR log 8684 13568 Internal Server Error: /api/auth/verify
[2025-05-16 19:46:30,876] ERROR log 8684 13568 Internal Server Error: /api/auth/verify
[2025-05-16 20:06:05,388] ERROR log 8684 9012 Internal Server Error: /api/users/following/status/4
[2025-05-16 20:06:22,867] ERROR log 8684 25128 Internal Server Error: /api/users/following/status/4
[2025-05-16 20:06:23,023] ERROR log 8684 24844 Internal Server Error: /api/users/following/status/4
[2025-05-16 20:07:43,212] ERROR log 8684 17416 Internal Server Error: /api/users/following/status/4
[2025-05-16 20:08:32,800] ERROR log 8684 24652 Internal Server Error: /api/users/following/status/4
[2025-05-16 20:08:51,930] ERROR log 8684 24652 Internal Server Error: /api/users/following/status/4
[2025-05-16 20:09:10,943] ERROR log 8684 24652 Internal Server Error: /api/users/following/status/4
[2025-05-16 20:09:36,665] ERROR log 8684 22116 Internal Server Error: /api/users/following/status/4
[2025-05-16 20:10:03,494] ERROR log 8684 22996 Internal Server Error: /api/users/following/status/4
[2025-05-16 20:14:21,741] ERROR log 8684 15384 Internal Server Error: /api/profile/3
[2025-05-16 20:14:26,821] ERROR log 8684 9528 Internal Server Error: /api/profile/4
[2025-05-16 20:14:27,115] ERROR log 8684 25168 Internal Server Error: /api/users/following/status/3/4
[2025-05-16 20:14:27,393] ERROR log 8684 25224 Internal Server Error: /api/users/following/status/3/4
[2025-05-16 20:17:08,665] ERROR log 8684 15560 Internal Server Error: /api/auth/verify
[2025-05-16 20:17:08,713] ERROR log 8684 15560 Internal Server Error: /api/auth/verify
[2025-05-16 20:17:09,042] ERROR log 8684 15560 Internal Server Error: /api/auth/verify
[2025-05-16 20:19:29,696] ERROR log 8684 23372 Internal Server Error: /api/auth/verify
[2025-05-16 20:19:29,754] ERROR log 8684 23372 Internal Server Error: /api/auth/verify
[2025-05-16 20:19:29,854] ERROR log 8684 23372 Internal Server Error: /api/auth/verify
[2025-05-16 20:19:29,964] ERROR log 8684 23372 Internal Server Error: /api/auth/verify
[2025-05-16 20:21:12,587] ERROR log 8684 17660 Internal Server Error: /api/auth/verify
[2025-05-16 20:21:12,648] ERROR log 8684 17660 Internal Server Error: /api/auth/verify
[2025-05-16 20:21:12,781] ERROR log 8684 17660 Internal Server Error: /api/auth/verify
[2025-05-18 12:32:00,450] ERROR log 23600 24808 Internal Server Error: /api/auth/verify
[2025-05-18 12:32:00,555] ERROR log 23600 24808 Internal Server Error: /api/auth/verify
[2025-05-18 12:32:00,747] ERROR log 23600 24808 Internal Server Error: /api/auth/verify
[2025-05-18 13:12:34,705] ERROR log 23600 24484 Internal Server Error: /api/auth/verify
[2025-05-18 13:13:05,492] ERROR log 23600 21972 Internal Server Error: /api/auth/verify
[2025-05-18 13:14:29,163] ERROR log 23600 12044 Internal Server Error: /api/auth/verify
[2025-05-18 13:14:29,224] ERROR log 23600 12044 Internal Server Error: /api/auth/verify
[2025-05-18 13:14:29,320] ERROR log 23600 12044 Internal Server Error: /api/auth/verify
[2025-05-18 13:15:38,724] ERROR log 23600 26612 Internal Server Error: /api/auth/verify
[2025-05-18 14:14:34,664] ERROR log 9528 14880 Internal Server Error: /api/auth/verify
[2025-05-18 14:14:34,720] ERROR log 9528 14880 Internal Server Error: /api/auth/verify
[2025-05-18 14:14:34,797] ERROR log 9528 14880 Internal Server Error: /api/auth/verify
[2025-05-18 14:16:10,455] ERROR log 9528 5824 Internal Server Error: /api/auth/verify
[2025-05-18 14:17:41,940] ERROR log 9528 23304 Internal Server Error: /api/auth/verify
[2025-05-18 14:18:58,885] ERROR log 9528 27316 Internal Server Error: /api/auth/verify
[2025-05-18 14:18:58,922] ERROR log 9528 27316 Internal Server Error: /api/auth/verify
[2025-05-18 14:18:58,997] ERROR log 9528 27316 Internal Server Error: /api/auth/verify
[2025-05-18 14:20:07,715] ERROR log 9528 8784 Internal Server Error: /api/auth/verify
[2025-05-18 14:25:05,173] ERROR log 9528 18996 Internal Server Error: /api/auth/verify
